[2025-05-24T14:35:13.232+0000] {task_context_logger.py:104} WARNING - Marking task instance <TaskInstance: fetch_and_store_amazon_books.fetch_book_data scheduled__2024-07-01T00:00:00+00:00 [queued]> stuck in queued as failed. If the task instance has available retries, it will be retried.
[2025-05-24T14:35:14.249+0000] {task_context_logger.py:104} ERROR - Executor reports task instance <TaskInstance: fetch_and_store_amazon_books.fetch_book_data scheduled__2024-07-01T00:00:00+00:00 [queued]> finished (failed) although the task says it's queued. (Info: None) Was the task killed externally?
