[2025-05-24T16:25:27.348+0000] {task_context_logger.py:104} WARNING - Marking task instance <TaskInstance: fetch_and_store_amazon_books.fetch_book_data scheduled__2025-05-23T00:00:00+00:00 [queued]> stuck in queued as failed. If the task instance has available retries, it will be retried.
[2025-05-24T16:25:28.443+0000] {task_context_logger.py:104} ERROR - Executor reports task instance <TaskInstance: fetch_and_store_amazon_books.fetch_book_data scheduled__2025-05-23T00:00:00+00:00 [queued]> finished (failed) although the task says it's queued. (Info: None) Was the task killed externally?
[2025-05-30T08:12:14.230+0000] {task_context_logger.py:104} WARNING - Marking task instance <TaskInstance: fetch_and_store_amazon_books.fetch_book_data scheduled__2025-05-23T00:00:00+00:00 [queued]> stuck in queued as failed. If the task instance has available retries, it will be retried.
[2025-05-30T08:12:15.205+0000] {task_context_logger.py:104} ERROR - Executor reports task instance <TaskInstance: fetch_and_store_amazon_books.fetch_book_data scheduled__2025-05-23T00:00:00+00:00 [queued]> finished (failed) although the task says it's queued. (Info: None) Was the task killed externally?
